Workbook

Sheet Parametres
A1: Paramètres du projet
A2: Modifiez uniquement les cellules jaunes ; tout le reste se recalcule automatiquement.
A4: Taux horaire — réalisation ($/h) | B4: 25
A5: Taux horaire — gestion ($/h) | B5: 30
A6: Taux horaire — facturation client ($/h) | B6: 45
A7: Provision pour aléas (%) | B7: 0.1
A9: Fournitures (détail)
A10: Onduleur (UPS) — Lot 2 | B10: 150
A11: Disque de sauvegarde — Lot 4 | B11: 120
A12: ESP32 et capteurs — Lot 6 | B12: 140
A13: Câblage et divers — Lot 8 | B13: 90
A14: Total fournitures | B14: =SUM(B10:B13) -> 500
A16: Premier jour de la semaine 6 (lundi) | B16: 46293

Sheet OTP
A1: Liste des tâches — Organigramme technique de projet (OTP)
A2: Coût = Durée × taux (réalisation ou gestion, selon la colonne Type). Modifiez les durées (bleu) au besoin.
A3: No | B3: Désignation de la tâche | C3: Lot | D3: Ressource | E3: Type | F3: Durée (h) | G3: Début | H3: Fin | I3: Coût ($) | J3: Sem. début | K3: Sem. fin
A4: T0.1 | B4: Rencontres hebdomadaires de suivi | C4: Lot 0 | D4: Chef de projet | E4: Gestion | F4: 20 | G4: =Parametres!$B$16+7*(J4-6) -> 46293 | H4: =Parametres!$B$16+7*(K4-6)+4 -> 46360 | I4: =IF(E4="Gestion",F4*Parametres!$B$5,F4*Parametres!$B$4) -> 600 | J4: 6 | K4: 15
A5: T0.2 | B5: Mise à jour de l'AMDEC et du budget à jour | C5: Lot 0 | D5: Chef de projet | E5: Gestion | F5: 10 | G5: =Parametres!$B$16+7*(J5-6) -> 46293 | H5: =Parametres!$B$16+7*(K5-6)+4 -> 46360 | I5: =IF(E5="Gestion",F5*Parametres!$B$5,F5*Parametres!$B$4) -> 300 | J5: 6 | K5: 15
A6: T0.3 | B6: Coordination et comptes rendus | C6: Lot 0 | D6: Chef de projet | E6: Gestion | F6: 10 | G6: =Parametres!$B$16+7*(J6-6) -> 46293 | H6: =Parametres!$B$16+7*(K6-6)+4 -> 46360 | I6: =IF(E6="Gestion",F6*Parametres!$B$5,F6*Parametres!$B$4) -> 300 | J6: 6 | K6: 15
A7: T0.4 | B7: Participation des équipiers aux rencontres de suivi | C7: Lot 0 | D7: Équipe | E7: Réalisation | F7: 30 | G7: =Parametres!$B$16+7*(J7-6) -> 46293 | H7: =Parametres!$B$16+7*(K7-6)+4 -> 46360 | I7: =IF(E7="Gestion",F7*Parametres!$B$5,F7*Parametres!$B$4) -> 750 | J7: 6 | K7: 15
A8: T1.1 | B8: Installation et configuration de Proxmox VE | C8: Lot 1 | D8: Loucas | E8: Réalisation | F8: 8 | G8: =Parametres!$B$16+7*(J8-6) -> 46293 | H8: =Parametres!$B$16+7*(K8-6)+4 -> 46297 | I8: =IF(E8="Gestion",F8*Parametres!$B$5,F8*Parametres!$B$4) -> 200 | J8: 6 | K8: 6
A9: T1.2 | B9: Réseau physique et configuration des VLAN | C9: Lot 1 | D9: Loucas | E9: Réalisation | F9: 8 | G9: =Parametres!$B$16+7*(J9-6) -> 46293 | H9: =Parametres!$B$16+7*(K9-6)+4 -> 46304 | I9: =IF(E9="Gestion",F9*Parametres!$B$5,F9*Parametres!$B$4) -> 200 | J9: 6 | K9: 7
A10: T1.3 | B10: Provisionnement des VM/LXC avec Terraform | C10: Lot 1 | D10: Alexy | E10: Réalisation | F10: 7 | G10: =Parametres!$B$16+7*(J10-6) -> 46300 | H10: =Parametres!$B$16+7*(K10-6)+4 -> 46304 | I10: =IF(E10="Gestion",F10*Parametres!$B$5,F10*Parametres!$B$4) -> 175 | J10: 7 | K10: 7
A11: T1.4 | B11: Playbooks Ansible (automatisation centralisée) | C11: Lot 1 | D11: Nicolas-André | E11: Réalisation | F11: 8 | G11: =Parametres!$B$16+7*(J13-6) -> 46300 | H11: =Parametres!$B$16+7*(K11-6)+4 -> 46311 | I11: =IF(E11="Gestion",F11*Parametres!$B$5,F11*Parametres!$B$4) -> 200 | J11: 7 | K11: 8
A12: T1.5 | B12: Orchestration de conteneurs avec Kubernetes (k3s) | C12: Lot 1 | D12: Alexy | E12: Réalisation | F12: 30 | G12: =Parametres!$B$16+7*(J13-6) -> 46300 | H12: =Parametres!$B$16+7*(K12-6)+4 -> 46346 | I12: =IF(E12="Gestion",F12*Parametres!$B$5,F12*Parametres!$B$4) -> 750 | J12: 7 | K12: 13
A13: T1.6 | B13: Plan d'adressage IP et segmentation VLAN | C13: Lot 1 | D13: Nicolas-André | E13: Réalisation | F13: 6 | G13: =Parametres!$B$16+7*(J13-6) -> 46300 | H13: =Parametres!$B$16+7*(K13-6)+4 -> 46304 | I13: =IF(E13="Gestion",F13*Parametres!$B$5,F13*Parametres!$B$4) -> 150 | J13: 7 | K13: 7
A14: T2.1 | B14: Installation du pare-feu pfSense/OPNsense | C14: Lot 2 | D14: Nicolas-André | E14: Réalisation | F14: 8 | G14: =Parametres!$B$16+7*(J14-6) -> 46307 | H14: =Parametres!$B$16+7*(K14-6)+4 -> 46311 | I14: =IF(E14="Gestion",F14*Parametres!$B$5,F14*Parametres!$B$4) -> 200 | J14: 8 | K14: 8
A15: T2.2 | B15: Configuration du VPN avec Tailscale | C15: Lot 2 | D15: Loucas | E15: Réalisation | F15: 8 | G15: =Parametres!$B$16+7*(J15-6) -> 46307 | H15: =Parametres!$B$16+7*(K15-6)+4 -> 46318 | I15: =IF(E15="Gestion",F15*Parametres!$B$5,F15*Parametres!$B$4) -> 200 | J15: 8 | K15: 9
A16: T2.3 | B16: Règles de pare-feu et segmentation | C16: Lot 2 | D16: Nicolas-André | E16: Réalisation | F16: 6 | G16: =Parametres!$B$16+7*(J16-6) -> 46314 | H16: =Parametres!$B$16+7*(K16-6)+4 -> 46318 | I16: =IF(E16="Gestion",F16*Parametres!$B$5,F16*Parametres!$B$4) -> 150 | J16: 9 | K16: 9
A17: T2.4 | B17: Reverse proxy et HTTPS avec Caddy | C17: Lot 2 | D17: Loucas | E17: Réalisation | F17: 6 | G17: =Parametres!$B$16+7*(J17-6) -> 46314 | H17: =Parametres!$B$16+7*(K17-6)+4 -> 46318 | I17: =IF(E17="Gestion",F17*Parametres!$B$5,F17*Parametres!$B$4) -> 150 | J17: 9 | K17: 9
A18: T3.1 | B18: Service VoIP avec Asterisk | C18: Lot 3 | D18: Alexy | E18: Réalisation | F18: 5 | G18: =Parametres!$B$16+7*(J18-6) -> 46321 | H18: =Parametres!$B$16+7*(K18-6)+4 -> 46332 | I18: =IF(E18="Gestion",F18*Parametres!$B$5,F18*Parametres!$B$4) -> 125 | J18: 10 | K18: 11
A19: T3.2 | B19: Serveur de développement web (Apache, MariaDB, PHP) | C19: Lot 3 | D19: Alexy | E19: Réalisation | F19: 4 | G19: =Parametres!$B$16+7*(J19-6) -> 46321 | H19: =Parametres!$B$16+7*(K19-6)+4 -> 46332 | I19: =IF(E19="Gestion",F19*Parametres!$B$5,F19*Parametres!$B$4) -> 100 | J19: 10 | K19: 11
A20: T3.3 | B20: Supervision des ressources avec Netdata | C20: Lot 3 | D20: Alexy | E20: Réalisation | F20: 8 | G20: =Parametres!$B$16+7*(J20-6) -> 46328 | H20: =Parametres!$B$16+7*(K20-6)+4 -> 46332 | I20: =IF(E20="Gestion",F20*Parametres!$B$5,F20*Parametres!$B$4) -> 200 | J20: 11 | K20: 11
A21: T4.1 | B21: Déploiement d'Active Directory Domain Services | C21: Lot 4 | D21: Loucas | E21: Réalisation | F21: 8 | G21: =Parametres!$B$16+7*(J21-6) -> 46321 | H21: =Parametres!$B$16+7*(K21-6)+4 -> 46325 | I21: =IF(E21="Gestion",F21*Parametres!$B$5,F21*Parametres!$B$4) -> 200 | J21: 10 | K21: 10
A22: T4.2 | B22: Serveur de courriel avec hMailServer | C22: Lot 4 | D22: Joshua | E22: Réalisation | F22: 10 | G22: =Parametres!$B$16+7*(J22-6) -> 46321 | H22: =Parametres!$B$16+7*(K22-6)+4 -> 46332 | I22: =IF(E22="Gestion",F22*Parametres!$B$5,F22*Parametres!$B$4) -> 250 | J22: 10 | K22: 11
A23: T4.3 | B23: Gestion des tickets avec osTicket | C23: Lot 4 | D23: Joshua | E23: Réalisation | F23: 8 | G23: =Parametres!$B$16+7*(J23-6) -> 46321 | H23: =Parametres!$B$16+7*(K23-6)+4 -> 46332 | I23: =IF(E23="Gestion",F23*Parametres!$B$5,F23*Parametres!$B$4) -> 200 | J23: 10 | K23: 11
A24: T4.4 | B24: Sauvegardes avec Veeam Backup & Replication | C24: Lot 4 | D24: Joshua | E24: Réalisation | F24: 10 | G24: =Parametres!$B$16+7*(J24-6) -> 46328 | H24: =Parametres!$B$16+7*(K24-6)+4 -> 46332 | I24: =IF(E24="Gestion",F24*Parametres!$B$5,F24*Parametres!$B$4) -> 250 | J24: 11 | K24: 11
... A39: T8.4 | B39: Préparation de la présentation finale | C39: Lot 8 | D39: Équipe | E39: Réalisation | F39: 8 | G39: =Parametres!$B$16+7*(J39-6) -> 46356 | H39: =Parametres!$B$16+7*(K39-6)+4 -> 46360 | I39: =IF(E39="Gestion",F39*Parametres!$B$5,F39*Parametres!$B$4) -> 200 | J39: 15 | K39: 15
A40: Total | F40: =SUM(F4:F39) -> 346 | I40: =SUM(I4:I39) -> 8850
B42: Résumé par type | D42: Charge par ressource (réalisation)
B43: Heures de réalisation | C43: =SUMIF(E4:E39,"Réalisation",F4:F39) -> 306 | D43: Ressource | E43: Heures
B44: Heures de gestion | C44: =SUMIF(E4:E39,"Gestion",F4:F39) -> 40 | D44: Nicolas-André | E44: =SUMIF(D4:D39,D44,F4:F39) -> 48
B45: Coût de réalisation | C45: =SUMIF(E4:E39,"Réalisation",I4:I39) -> 7650 | D45: Alexy | E45: =SUMIF(D4:D39,D45,F4:F39) -> 60
B46: Coût de gestion | C46: =SUMIF(E4:E39,"Gestion",I4:I39) -> 1200 | D46: Joshua | E46: =SUMIF(D4:D39,D46,F4:F39) -> 50
D47: Loucas | E47: =SUMIF(D4:D39,D47,F4:F39) -> 60
D48: Équipe | E48: =SUMIF(D4:D39,D48,F4:F39) -> 88

Sheet Budget
A1: Budget détaillé
A3: A. Coût du personnel pour l'entreprise (coût interne)
A4: Lot | B4: Heures | C4: Main-d'œuvre ($) | D4: Fournitures ($) | E4: Total ($)
A5: Lot 0 | B5: =SUMIF(OTP!$C:$C,A5,OTP!$F:$F) -> 70 | C5: =SUMIF(OTP!$C:$C,A5,OTP!$I:$I) -> 1950 | D5: 0 | E5: =C5+D5 -> 1950
A6: Lot 1 | B6: =SUMIF(OTP!$C:$C,A6,OTP!$F:$F) -> 67 | C6: =SUMIF(OTP!$C:$C,A6,OTP!$I:$I) -> 1675 | D6: 0 | E6: =C6+D6 -> 1675
A7: Lot 2 | B7: =SUMIF(OTP!$C:$C,A7,OTP!$F:$F) -> 28 | C7: =SUMIF(OTP!$C:$C,A7,OTP!$I:$I) -> 700 | D7: =Parametres!$B$10 -> 150 | E7: =C7+D7 -> 850
A8: Lot 3 | B8: =SUMIF(OTP!$C:$C,A8,OTP!$F:$F) -> 17 | C8: =SUMIF(OTP!$C:$C,A8,OTP!$I:$I) -> 425 | D8: 0 | E8: =C8+D8 -> 425
A9: Lot 4 | B9: =SUMIF(OTP!$C:$C,A9,OTP!$F:$F) -> 44 | C9: =SUMIF(OTP!$C:$C,A9,OTP!$I:$I) -> 1100 | D9: =Parametres!$B$11 -> 120 | E9: =C9+D9 -> 1220
A10: Lot 5 | B10: =SUMIF(OTP!$C:$C,A10,OTP!$F:$F) -> 24 | C10: =SUMIF(OTP!$C:$C,A10,OTP!$I:$I) -> 600 | D10: 0 | E10: =C10+D10 -> 600
A11: Lot 6 | B11: =SUMIF(OTP!$C:$C,A11,OTP!$F:$F) -> 26 | C11: =SUMIF(OTP!$C:$C,A11,OTP!$I:$I) -> 650 | D11: =Parametres!$B$12 -> 140 | E11: =C11+D11 -> 790
A12: Lot 7 | B12: =SUMIF(OTP!$C:$C,A12,OTP!$F:$F) -> 32 | C12: =SUMIF(OTP!$C:$C,A12,OTP!$I:$I) -> 800 | D12: 0 | E12: =C12+D12 -> 800
A13: Lot 8 | B13: =SUMIF(OTP!$C:$C,A13,OTP!$F:$F) -> 38 | C13: =SUMIF(OTP!$C:$C,A13,OTP!$I:$I) -> 950 | D13: =Parametres!$B$13 -> 90 | E13: =C13+D13 -> 1040
A14: Sous-total | B14: =SUM(B5:B13) -> 346 | C14: =SUM(C5:C13) -> 8850 | D14: =SUM(D5:D13) -> 500 | E14: =SUM(E5:E13) -> 9350
A15: Provision pour aléas | D15: =Parametres!$B$7 -> 0.1 | E15: =Parametres!$B$7*(C14+D14) -> 935
A16: Coût interne total | E16: =E14+E15 -> 10285
A18: B. Coût du personnel pour le client
A19: Poste | B19: Détail | C19: Montant ($)
A20: Main-d'œuvre | B20: Total des heures × taux client | C20: =OTP!$F$40*Parametres!$B$6 -> 15570
A21: Fournitures | B21: au coût | C21: =Parametres!$B$14 -> 500
A22: Provision pour aléas | B22: 10 % de la main-d'œuvre et des fournitures | C22: =Parametres!$B$7*(C20+C21) -> 1607
A23: Prix total offert au client | C23: =SUM(C20:C22) -> 17677
A25: C. Synthèse budgétaire
A26: Indicateur | B26: Montant
A27: Coût du personnel pour l'entreprise | B27: =C14 -> 8850
A28: Coût du personnel facturé au client | B28: =C20 -> 15570
A29: Écart sur la main-d'œuvre (marge) | B29: =B28-B27 -> 6720
A30: Coût interne total (fournitures et aléas compris) | B30: =E16 -> 10285
A31: Prix total offert au client | B31: =C23 -> 17677
A32: Marge brute du projet ($) | B32: =B31-B30 -> 7392
A33: Marge brute du projet (%) | B33: =B32/B31 -> 0.4181705

Sheet Budget à jour
A1: Budget à jour — suivi hebdomadaire de l'implantation
A2: Jaune/bleu = saisies du chef de projet en poste ; vert = liens vers les autres onglets ; noir = calculs. À la semaine 0 (avant l'implantation), le budget à jour est identique au budget initial.
A3: Une modification approuvée (section 5) est convertie en heures au taux moyen du lot et s'ajoute aux heures prévues ; « Ajustement des heures restantes » sert à toute autre révision d'estimation.
A4: Semaine de suivi (dernière semaine saisie ; 0 = avant S6) | B4: 0
A6: 1. Budget à jour par lot (coût interne)
A7: Lot | B7: Budget initial ($) | C7: Modifications approuvées ($) | D7: Budget à jour ($) | E7: Heures prévues | F7: Taux moyen ($/h) | G7: Heures réelles cumulées | H7: Fournitures réelles ($) | I7: Coût réel à ce jour ($) | J7: Ajustement des heures restantes (h) | K7: Reste à engager ($) | L7: Prévision à terminaison ($) | M7: Écart : budget à jour − prévision ($)
A8: Lot 0 | B8: =Budget!E5 -> 1950 | C8: =SUMIFS($E$87:$E$116,$D$87:$D$116,$A8,$C$87:$C$116,">1") -> 0 | D8: =B8+C8 -> 1950 | E8: =Budget!B5 -> 70 | F8: =IF(E8=0,0,Budget!C5/E8) -> 27.857143 | G8: =L46 -> 0 | H8: 0 | I8: =G8*F8+H8 -> 0 | J8: 0 | K8: =(MAX(0,E8+IF(F8=0,0,C8/F8)-G8)+J8)*F8+MAX(0,Budget!D5-H8) -> 1950 | L8: =I8+K8 -> 1950 | M8: =D8-L8 -> 0
A9: Lot 1 | B9: =Budget!E6 -> 1675 | C9: =SUMIFS($E$87:$E$116,$D$87:$D$116,$A9,$C$87:$C$116,">1") -> 0 | D9: =B9+C9 -> 1675 | E9: =Budget!B6 -> 67 | F9: =IF(E9=0,0,Budget!C6/E9) -> 25 | G9: =L47 -> 0 | H9: 0 | I9: =G9*F9+H9 -> 0 | J9: 0 | K9: =(MAX(0,E9+IF(F9=0,0,C9/F9)-G9)+J9)*F9+MAX(0,Budget!D6-H9) -> 1675 | L9: =I9+K9 -> 1675 | M9: =D9-L9 -> 0
A10: Lot 2 | B10: =Budget!E7 -> 850 | C10: =SUMIFS($E$87:$E$116,$D$87:$D$116,$A10,$C$87:$C$116,">1") -> 0 | D10: =B10+C10 -> 850 | E10: =Budget!B7 -> 28 | F10: =IF(E10=0,0,Budget!C7/E10) -> 25 | G10: =L48 -> 0 | H10: 0 | I10: =G10*F10+H10 -> 0 | J10: 0 | K10: =(MAX(0,E10+IF(F10=0,0,C10/F10)-G10)+J10)*F10+MAX(0,Budget!D7-H10) -> 850 | L10: =I10+K10 -> 850 | M10: =D10-L10 -> 0
A11: Lot 3 | B11: =Budget!E8 -> 425 | C11: =SUMIFS($E$87:$E$116,$D$87:$D$116,$A11,$C$87:$C$116,">1") -> 0 | D11: =B11+C11 -> 425 | E11: =Budget!B8 -> 17 | F11: =IF(E11=0,0,Budget!C8/E11) -> 25 | G11: =L49 -> 0 | H11: 0 | I11: =G11*F11+H11 -> 0 | J11: 0 | K11: =(MAX(0,E11+IF(F11=0,0,C11/F11)-G11)+J11)*F11+MAX(0,Budget!D8-H11) -> 425 | L11: =I11+K11 -> 425 | M11: =D11-L11 -> 0
A12: Lot 4 | B12: =Budget!E9 -> 1220 | C12: =SUMIFS($E$87:$E$116,$D$87:$D$116,$A12,$C$87:$C$116,">1") -> 0 | D12: =B12+C12 -> 1220 | E12: =Budget!B9 -> 44 | F12: =IF(E12=0,0,Budget!C9/E12) -> 25 | G12: =L50 -> 0 | H12: 0 | I12: =G12*F12+H12 -> 0 | J12: 0 | K12: =(MAX(0,E12+IF(F12=0,0,C12/F12)-G12)+J12)*F12+MAX(0,Budget!D9-H12) -> 1220 | L12: =I12+K12 -> 1220 | M12: =D12-L12 -> 0
A13: Lot 5 | B13: =Budget!E10 -> 600 | C13: =SUMIFS($E$87:$E$116,$D$87:$D$116,$A13,$C$87:$C$116,">1") -> 0 | D13: =B13+C13 -> 600 | E13: =Budget!B10 -> 24 | F13: =IF(E13=0,0,Budget!C10/E13) -> 25 | G13: =L51 -> 0 | H13: 0 | I13: =G13*F13+H13 -> 0 | J13: 0 | K13: =(MAX(0,E13+IF(F13=0,0,C13/F13)-G13)+J13)*F13+MAX(0,Budget!D10-H13) -> 600 | L13: =I13+K13 -> 600 | M13: =D13-L13 -> 0
A14: Lot 6 | B14: =Budget!E11 -> 790 | C14: =SUMIFS($E$87:$E$116,$D$87:$D$116,$A14,$C$87:$C$116,">1") -> 0 | D14: =B14+C14 -> 790 | E14: =Budget!B11 -> 26 | F14: =IF(E14=0,0,Budget!C11/E14) -> 25 | G14: =L52 -> 0 | H14: 0 | I14: =G14*F14+H14 -> 0 | J14: 0 | K14: =(MAX(0,E14+IF(F14=0,0,C14/F14)-G14)+J14)*F14+MAX(0,Budget!D11-H14) -> 790 | L14: =I14+K14 -> 790 | M14: =D14-L14 -> 0
A15: Lot 7 | B15: =Budget!E12 -> 800 | C15: =SUMIFS($E$87:$E$116,$D$87:$D$116,$A15,$C$87:$C$116,">1") -> 0 | D15: =B15+C15 -> 800 | E15: =Budget!B12 -> 32 | F15: =IF(E15=0,0,Budget!C12/E15) -> 25 | G15: =L53 -> 0 | H15: 0 | I15: =G15*F15+H15 -> 0 | J15: 0 | K15: =(MAX(0,E15+IF(F15=0,0,C15/F15)-G15)+J15)*F15+MAX(0,Budget!D12-H15) -> 800 | L15: =I15+K15 -> 800 | M15: =D15-L15 -> 0
A16: Lot 8 | B16: =Budget!E13 -> 1040 | C16: =SUMIFS($E$87:$E$116,$D$87:$D$116,$A16,$C$87:$C$116,">1") -> 0 | D16: =B16+C16 -> 1040 | E16: =Budget!B13 -> 38 | F16: =IF(E16=0,0,Budget!C13/E16) -> 25 | G16: =L54 -> 0 | H16: 0 | I16: =G16*F16+H16 -> 0 | J16: 0 | K16: =(MAX(0,E16+IF(F16=0,0,C16/F16)-G16)+J16)*F16+MAX(0,Budget!D13-H16) -> 1040 | L16: =I16+K16 -> 1040 | M16: =D16-L16 -> 0
A17: Total des lots | B17: =SUM(B8:B16) -> 9350 | C17: =SUM(C8:C16) -> 0 | D17: =SUM(D8:D16) -> 9350 | E17: =SUM(E8:E16) -> 346 | G17: =SUM(G8:G16) -> 0 | H17: =SUM(H8:H16) -> 0 | I17: =SUM(I8:I16) -> 0 | J17: =SUM(J8:J16) -> 0 | K17: =SUM(K8:K16) -> 9350 | L17: =SUM(L8:L16) -> 9350 | M17: =SUM(M8:M16) -> 0
A18: Provision pour aléas (restante) | B18: =Budget!E15 -> 935 | C18: =-SUMIFS($E$87:$E$116,$F$87:$F$116,"Oui",$C$87:$C$116,3) -> 0 | D18: =B18+C18 -> 935
A19: Budget total à jour (lots + provision) | B19: =B17+B18 -> 10285 | C19: =C17+C18 -> 0 | D19: =D17+D18 -> 10285
A21: 2. Synthèse budgétaire à la semaine de suivi
A22: Indicateur | B22: Valeur
A23: Coût interne — budget initial | B23: =Budget!E16 -> 10285
A24: Coût interne — budget à jour | B24: =D19 -> 10285
A25: Coût réel à ce jour | B25: =I17 -> 0
A26: Reste à engager (estimation) | B26: =K17 -> 9350
A27: Prévision à terminaison (avant provision) | B27: =L17 -> 9350
A28: Provision pour aléas — initiale | B28: =B18 -> 935
A29: Provision pour aléas — consommée | B29: =-C18 -> 0
A30: Provision pour aléas — restante | B30: =D18 -> 935
A31: Marge de manœuvre des lots (budget des lots − prévision) | B31: =D17-L17 -> 0
A32: Dépassement non couvert par la provision | B32: =MAX(0,L17-D17-D18) -> 0
A33: Prix total offert au client | B33: =Budget!C23 -> 17677
A34: Coût à terminaison retenu (prévision + provision restante) | B34: =L17+D18 -> 10285
A35: Marge brute initiale ($) | B35: =Budget!B32 -> 7392
A36: Marge brute prévue ($) | B36: =B33-B34 -> 7392
A37: Marge brute prévue (%) | B37: =IF(B33=0,0,B36/B33) -> 0.4181705
A39: Heures prévues cumulées à la semaine de suivi (courbe en S) | B39: =IF($B$4=0,0,IF($B$4>=6,INDEX(Planification!$C$14:$L$14,1,MIN($B$4,15)-5),"Semaine invalide")) -> 0
A40: Heures réelles cumulées | B40: =G17 -> 0
A41: Écart en heures (réel − prévu) | B41: =IF(ISNUMBER(B39),B40-B39,"s. o.") -> 0
A42: Indice d'avancement (réel ÷ prévu) | B42: =IF(NOT(ISNUMBER(B39)),"s. o.",IF(B39=0,"s. o.",B40/B39)) -> s. o.
A44: 3. Saisie hebdomadaire des heures réelles (h)
...

Sheet AMDEC
A1: Analyse des risques — AMDEC
A2: Criticité = Gravité × Fréquence × Non-détection. Les risques ≥ seuil sont surlignés. | H2: Seuil | I2: 15
A3: Fonction | B3: Mode de défaillance | C3: Effet | D3: Cause | E3: G | F3: F | G3: ND | H3: Criticité | I3: Action préventive / corrective | J3: Responsable | K3: Statut | L3: Dernière révision | M3: F après action | N3: ND après action | O3: Criticité après action
A4: Serveur Proxmox | B4: Panne matérielle | C4: Arrêt de tous les services | D4: Défaillance disque ou alimentation | E4: 4 | F4: 2 | G4: 2 | H4: =E4*F4*G4 -> 16 | I4: Sauvegardes régulières sur disque externe (Veeam), configuration de l'hôte exportée et documentée pour le reconstruire | J4: N.-A. Anillo | K4: Ouvert | L4: 46286 | M4: 1 | N4: 2 | O4: =E4*M4*N4 -> 8
A5: Alimentation électrique | B5: Coupure de courant | C5: Arrêt des services | D5: Panne du réseau électrique | E5: 3 | F5: 2 | G5: 1 | H5: =E5*F5*G5 -> 6 | I5: Onduleur (UPS) | J5: L. Viens | K5: Ouvert | L5: 46286 | M5: 1 | N5: 1 | O5: =E5*M5*N5 -> 3
A6: Pare-feu / VPN (pfSense, Tailscale) | B6: Règles mal configurées | C6: Accès non autorisé au réseau | D6: Erreur humaine | E6: 4 | F6: 2 | G6: 3 | H6: =E6*F6*G6 -> 24 | I6: Revue des règles par un second équipier, tests de chaque VLAN avant la mise en service, exportation de la configuration | J6: L. Viens | K6: Ouvert | L6: 46286 | M6: 1 | N6: 2 | O6: =E6*M6*N6 -> 8
A7: Sauvegardes (Veeam) | B7: Copie corrompue ou non testée | C7: Perte de données irrécupérable | D7: Absence de vérification | E7: 4 | F7: 2 | G7: 3 | H7: =E7*F7*G7 -> 24 | I7: Tests de restauration périodiques | J7: J. Leclerc | K7: Ouvert | L7: 46286 | M7: 1 | N7: 2 | O7: =E7*M7*N7 -> 8
A8: Hôte (ressources) | B8: Surcharge CPU / RAM | C8: Baisse de performance | D8: Sous-dimensionnement | E8: 2 | F8: 3 | G8: 2 | H8: =E8*F8*G8 -> 12 | I8: Supervision, quotas de ressources | J8: A. Després | K8: Ouvert | L8: 46286 | M8: 2 | N8: 1 | O8: =E8*M8*N8 -> 4
A9: Planification | B9: Durées sous-estimées | C9: Retard du projet | D9: Estimation optimiste | E9: 3 | F9: 3 | G9: 2 | H9: =E9*F9*G9 -> 18 | I9: Provision d'aléas, suivi hebdomadaire | J9: Chef de projet en poste | K9: Ouvert | L9: 46286 | M9: 2 | N9: 2 | O9: =E9*M9*N9 -> 12
A10: Équipe | B10: Indisponibilité d'un équipier | C10: Retard, surcharge | D10: Maladie, conflit d'horaire | E10: 2 | F10: 2 | G10: 2 | H10: =E10*F10*G10 -> 8 | I10: Rotation, documentation partagée | J10: Chef de projet en poste | K10: Ouvert | L10: 46286 | M10: 1 | N10: 2 | O10: =E10*M10*N10 -> 4
A11: Réseau (VLAN) | B11: Mauvaise segmentation | C11: Services isolés | D11: Configuration erronée | E11: 3 | F11: 2 | G11: 2 | H11: =E11*F11*G11 -> 12 | I11: Plan d'adressage validé, tests | J11: L. Viens | K11: Ouvert | L11: 46286 | M11: 1 | N11: 2 | O11: =E11*M11*N11 -> 6
A12: ESP32 / MQTT (Mosquitto) | B12: Module défaillant | C12: Fonction IoT non livrée | D12: Matériel ou micrologiciel | E12: 2 | F12: 2 | G12: 2 | H12: =E12*F12*G12 -> 8 | I12: Tests unitaires, module de rechange | J12: N.-A. Anillo | K12: Ouvert | L12: 46286 | M12: 1 | N12: 2 | O12: =E12*M12*N12 -> 4
A13: Reverse proxy / HTTPS (Caddy) | B13: Échec de renouvellement de certificat | C13: Services web inaccessibles en HTTPS | D13: Mauvaise configuration DNS ou pare-feu bloquant le défi ACME | E13: 3 | F13: 2 | G13: 2 | H13: =E13*F13*G13 -> 12 | I13: Surveillance des certificats, alerte avant expiration | J13: L. Viens | K13: Ouvert | L13: 46286 | M13: 1 | N13: 1 | O13: =E13*M13*N13 -> 3
A14: Automatisation (Terraform, Ansible) | B14: Script ou plan erroné appliqué | C14: Modification non désirée de l'infrastructure | D14: Erreur humaine, absence de revue | E14: 3 | F14: 2 | G14: 2 | H14: =E14*F14*G14 -> 12 | I14: Revue par les pairs, exécution en mode « plan » avant application | J14: N.-A. Anillo | K14: Ouvert | L14: 46286 | M14: 1 | N14: 2 | O14: =E14*M14*N14 -> 6

Sheet Planification
A1: Planification initiale — répartition de la charge et graphiques
A3: Lot | B3: Total (h) | C3: 6 | D3: 7 | E3: 8 | F3: 9 | G3: 10 | H3: 11 | I3: 12 | J3: 13 | K3: 14 | L3: 15 | M3: Début | N3: Fin | O3: Chemin critique ? | P3: Tâche (Gantt) | Q3: Début (sem.) | R3: Fin (sem.) | S3: Décalage | T3: Gestion (transversale) | U3: Hors chemin critique | V3: Chemin critique
A4: Lot 0 | B4: =SUMIF(OTP!$C:$C,A4,OTP!$F:$F) -> 70 | C4: =IF(AND(C$3>=$M4,C$3<=$N4),$B4/($N4-$M4+1),0) -> 7 | D4: =IF(AND(D$3>=$M4,D$3<=$N4),$B4/($N4-$M4+1),0) -> 7 | E4: =IF(AND(E$3>=$M4,E$3<=$N4),$B4/($N4-$M4+1),0) -> 7 | F4: =IF(AND(F$3>=$M4,F$3<=$N4),$B4/($N4-$M4+1),0) -> 7 | G4: =IF(AND(G$3>=$M4,G$3<=$N4),$B4/($N4-$M4+1),0) -> 7 | H4: =IF(AND(H$3>=$M4,H$3<=$N4),$B4/($N4-$M4+1),0) -> 7 | I4: =IF(AND(I$3>=$M4,I$3<=$N4),$B4/($N4-$M4+1),0) -> 7 | J4: =IF(AND(J$3>=$M4,J$3<=$N4),$B4/($N4-$M4+1),0) -> 7 | ... L4: =IF(AND(L$3>=$M4,L$3<=$N4),$B4/($N4-$M4+1),0) -> 7 | M4: =_xlfn.MINIFS(OTP!$J$4:$J$39,OTP!$C$4:$C$39,$A4) -> 6 | N4: =_xlfn.MAXIFS(OTP!$K$4:$K$39,OTP!$C$4:$C$39,$A4) -> 15 | O4: — | P4: =OTP!A4&" "&LEFT(OTP!B4,42) -> T0.1 Rencontres hebdomadaires de suivi | Q4: =OTP!J4 -> 6 | R4: =OTP!K4 -> 15 | S4: =Q4 -> 6 | T4: =IF(OTP!C4="Lot 0",R4-Q4+1,0) -> 10 | U4: =IF(AND(OTP!C4<>"Lot 0",INDEX($O$4:$O$12,MATCH(OTP!C4,$A$4:$A$12,0))<>"Oui"),R4-Q4+1,0) -> 0 | V4: =IF(AND(OTP!C4<>"Lot 0",INDEX($O$4:$O$12,MATCH(OTP!C4,$A$4:$A$12,0))="Oui"),R4-Q4+1,0) -> 0
A5: Lot 1 | B5: =SUMIF(OTP!$C:$C,A5,OTP!$F:$F) -> 67 | C5: =IF(AND(C$3>=$M5,C$3<=$N5),$B5/($N5-$M5+1),0) -> 8.375 | D5: =IF(AND(D$3>=$M5,D$3<=$N5),$B5/($N5-$M5+1),0) -> 8.375 | E5: =IF(AND(E$3>=$M5,E$3<=$N5),$B5/($N5-$M5+1),0) -> 8.375 | F5: =IF(AND(F$3>=$M5,F$3<=$N5),$B5/($N5-$M5+1),0) -> 8.375 | G5: =IF(AND(G$3>=$M5,G$3<=$N5),$B5/($N5-$M5+1),0) -> 8.375 | H5: =IF(AND(H$3>=$M5,H$3<=$N5),$B5/($N5-$M5+1),0) -> 8.375 | I5: =IF(AND(I$3>=$M5,I$3<=$N5),$B5/($N5-$M5+1),0) -> 8.375 | J5: =IF(AND(J$3>=$M5,J$3<=$N5),$B5/($N5-$M5+1),0) -> 8.375 | ... L5: =IF(AND(L$3>=$M5,L$3<=$N5),$B5/($N5-$M5+1),0) -> 0 | M5: =_xlfn.MINIFS(OTP!$J$4:$J$39,OTP!$C$4:$C$39,$A5) -> 6 | N5: =_xlfn.MAXIFS(OTP!$K$4:$K$39,OTP!$C$4:$C$39,$A5) -> 13 | O5: Oui | P5: =OTP!A5&" "&LEFT(OTP!B5,42) -> T0.2 Mise à jour de l'AMDEC et du budget à jour | Q5: =OTP!J5 -> 6 | R5: =OTP!K5 -> 15 | S5: =Q5 -> 6 | T5: =IF(OTP!C5="Lot 0",R5-Q5+1,0) -> 10 | U5: =IF(AND(OTP!C5<>"Lot 0",INDEX($O$4:$O$12,MATCH(OTP!C5,$A$4:$A$12,0))<>"Oui"),R5-Q5+1,0) -> 0 | V5: =IF(AND(OTP!C5<>"Lot 0",INDEX($O$4:$O$12,MATCH(OTP!C5,$A$4:$A$12,0))="Oui"),R5-Q5+1,0) -> 0
A6: Lot 2 | B6: =SUMIF(OTP!$C:$C,A6,OTP!$F:$F) -> 28 | C6: =IF(AND(C$3>=$M6,C$3<=$N6),$B6/($N6-$M6+1),0) -> 0 | D6: =IF(AND(D$3>=$M6,D$3<=$N6),$B6/($N6-$M6+1),0) -> 0 | E6: =IF(AND(E$3>=$M6,E$3<=$N6),$B6/($N6-$M6+1),0) -> 14 | F6: =IF(AND(F$3>=$M6,F$3<=$N6),$B6/($N6-$M6+1),0) -> 14 | G6: =IF(AND(G$3>=$M6,G$3<=$N6),$B6/($N6-$M6+1),0) -> 0 | H6: =IF(AND(H$3>=$M6,H$3<=$N6),$B6/($N6-$M6+1),0) -> 0 | I6: =IF(AND(I$3>=$M6,I$3<=$N6),$B6/($N6-$M6+1),0) -> 0 | J6: =IF(AND(J$3>=$M6,J$3<=$N6),$B6/($N6-$M6+1),0) -> 0 | ... L6: =IF(AND(L$3>=$M6,L$3<=$N6),$B6/($N6-$M6+1),0) -> 0 | M6: =_xlfn.MINIFS(OTP!$J$4:$J$39,OTP!$C$4:$C$39,$A6) -> 8 | N6: =_xlfn.MAXIFS(OTP!$K$4:$K$39,OTP!$C$4:$C$39,$A6) -> 9 | O6: Oui | P6: =OTP!A6&" "&LEFT(OTP!B6,42) -> T0.3 Coordination et comptes rendus | Q6: =OTP!J6 -> 6 | R6: =OTP!K6 -> 15 | S6: =Q6 -> 6 | T6: =IF(OTP!C6="Lot 0",R6-Q6+1,0) -> 10 | U6: =IF(AND(OTP!C6<>"Lot 0",INDEX($O$4:$O$12,MATCH(OTP!C6,$A$4:$A$12,0))<>"Oui"),R6-Q6+1,0) -> 0 | V6: =IF(AND(OTP!C6<>"Lot 0",INDEX($O$4:$O$12,MATCH(OTP!C6,$A$4:$A$12,0))="Oui"),R6-Q6+1,0) -> 0
A7: Lot 3 | B7: =SUMIF(OTP!$C:$C,A7,OTP!$F:$F) -> 17 | C7: =IF(AND(C$3>=$M7,C$3<=$N7),$B7/($N7-$M7+1),0) -> 0 | D7: =IF(AND(D$3>=$M7,D$3<=$N7),$B7/($N7-$M7+1),0) -> 0 | E7: =IF(AND(E$3>=$M7,E$3<=$N7),$B7/($N7-$M7+1),0) -> 0 | F7: =IF(AND(F$3>=$M7,F$3<=$N7),$B7/($N7-$M7+1),0) -> 0 | G7: =IF(AND(G$3>=$M7,G$3<=$N7),$B7/($N7-$M7+1),0) -> 8.5 | H7: =IF(AND(H$3>=$M7,H$3<=$N7),$B7/($N7-$M7+1),0) -> 8.5 | I7: =IF(AND(I$3>=$M7,I$3<=$N7),$B7/($N7-$M7+1),0) -> 0 | J7: =IF(AND(J$3>=$M7,J$3<=$N7),$B7/($N7-$M7+1),0) -> 0 | ... L7: =IF(AND(L$3>=$M7,L$3<=$N7),$B7/($N7-$M7+1),0) -> 0 | M7: =_xlfn.MINIFS(OTP!$J$4:$J$39,OTP!$C$4:$C$39,$A7) -> 10 | N7: =_xlfn.MAXIFS(OTP!$K$4:$K$39,OTP!$C$4:$C$39,$A7) -> 11 | O7: Oui | P7: =OTP!A7&" "&LEFT(OTP!B7,42) -> T0.4 Participation des équipiers aux rencontres | Q7: =OTP!J7 -> 6 | R7: =OTP!K7 -> 15 | S7: =Q7 -> 6 | T7: =IF(OTP!C7="Lot 0",R7-Q7+1,0) -> 10 | U7: =IF(AND(OTP!C7<>"Lot 0",INDEX($O$4:$O$12,MATCH(OTP!C7,$A$4:$A$12,0))<>"Oui"),R7-Q7+1,0) -> 0 | V7: =IF(AND(OTP!C7<>"Lot 0",INDEX($O$4:$O$12,MATCH(OTP!C7,$A$4:$A$12,0))="Oui"),R7-Q7+1,0) -> 0
A8: Lot 4 | B8: =SUMIF(OTP!$C:$C,A8,OTP!$F:$F) -> 44 | C8: =IF(AND(C$3>=$M8,C$3<=$N8),$B8/($N8-$M8+1),0) -> 0 | D8: =IF(AND(D$3>=$M8,D$3<=$N8),$B8/($N8-$M8+1),0) -> 0 | E8: =IF(AND(E$3>=$M8,E$3<=$N8),$B8/($N8-$M8+1),0) -> 0 | F8: =IF(AND(F$3>=$M8,F$3<=$N8),$B8/($N8-$M8+1),0) -> 0 | G8: =IF(AND(G$3>=$M8,G$3<=$N8),$B8/($N8-$M8+1),0) -> 22 | H8: =IF(AND(H$3>=$M8,H$3<=$N8),$B8/($N8-$M8+1),0) -> 22 | I8: =IF(AND(I$3>=$M8,I$3<=$N8),$B8/($N8-$M8+1),0) -> 0 | J8: =IF(AND(J$3>=$M8,J$3<=$N8),$B8/($N8-$M8+1),0) -> 0 | ... L8: =IF(AND(L$3>=$M8,L$3<=$N8),$B8/($N8-$M8+1),0) -> 0 | M8: =_xlfn.MINIFS(OTP!$J$4:$J$39,OTP!$C$4:$C$39,$A8) -> 10 | N8: =_xlfn.MAXIFS(OTP!$K$4:$K$39,OTP!$C$4:$C$39,$A8) -> 11 | O8: Oui | P8: =OTP!A8&" "&LEFT(OTP!B8,42) -> T1.1 Installation et configuration de Proxmox V | Q8: =OTP!J8 -> 6 | R8: =OTP!K8 -> 6 | S8: =Q8 -> 6 | T8: =IF(OTP!C8="Lot 0",R8-Q8+1,0) -> 0 | U8: =IF(AND(OTP!C8<>"Lot 0",INDEX($O$4:$O$12,MATCH(OTP!C8,$A$4:$A$12,0))<>"Oui"),R8-Q8+1,0) -> 0 | V8: =IF(AND(OTP!C8<>"Lot 0",INDEX($O$4:$O$12,MATCH(OTP!C8,$A$4:$A$12,0))="Oui"),R8-Q8+1,0) -> 1
A9: Lot 5 | B9: =SUMIF(OTP!$C:$C,A9,OTP!$F:$F) -> 24 | C9: =IF(AND(C$3>=$M9,C$3<=$N9),$B9/($N9-$M9+1),0) -> 0 | D9: =IF(AND(D$3>=$M9,D$3<=$N9),$B9/($N9-$M9+1),0) -> 0 | E9: =IF(AND(E$3>=$M9,E$3<=$N9),$B9/($N9-$M9+1),0) -> 0 | F9: =IF(AND(F$3>=$M9,F$3<=$N9),$B9/($N9-$M9+1),0) -> 0 | G9: =IF(AND(G$3>=$M9,G$3<=$N9),$B9/($N9-$M9+1),0) -> 0 | H9: =IF(AND(H$3>=$M9,H$3<=$N9),$B9/($N9-$M9+1),0) -> 0 | I9: =IF(AND(I$3>=$M9,I$3<=$N9),$B9/($N9-$M9+1),0) -> 24 | J9: =IF(AND(J$3>=$M9,J$3<=$N9),$B9/($N9-$M9+1),0) -> 0 | ... L9: =IF(AND(L$3>=$M9,L$3<=$N9),$B9/($N9-$M9+1),0) -> 0 | M9: =_xlfn.MINIFS(OTP!$J$4:$J$39,OTP!$C$4:$C$39,$A9) -> 12 | N9: =_xlfn.MAXIFS(OTP!$K$4:$K$39,OTP!$C$4:$C$39,$A9) -> 12 | O9: Non | P9: =OTP!A9&" "&LEFT(OTP!B9,42) -> T1.2 Réseau physique et configuration des VLAN | Q9: =OTP!J9 -> 6 | R9: =OTP!K9 -> 7 | S9: =Q9 -> 6 | T9: =IF(OTP!C9="Lot 0",R9-Q9+1,0) -> 0 | U9: =IF(AND(OTP!C9<>"Lot 0",INDEX($O$4:$O$12,MATCH(OTP!C9,$A$4:$A$12,0))<>"Oui"),R9-Q9+1,0) -> 0 | V9: =IF(AND(OTP!C9<>"Lot 0",INDEX($O$4:$O$12,MATCH(OTP!C9,$A$4:$A$12,0))="Oui"),R9-Q9+1,0) -> 2
A10: Lot 6 | B10: =SUMIF(OTP!$C:$C,A10,OTP!$F:$F) -> 26 | C10: =IF(AND(C$3>=$M10,C$3<=$N10),$B10/($N10-$M10+1),0) -> 0 | D10: =IF(AND(D$3>=$M10,D$3<=$N10),$B10/($N10-$M10+1),0) -> 0 | E10: =IF(AND(E$3>=$M10,E$3<=$N10),$B10/($N10-$M10+1),0) -> 0 | F10: =IF(AND(F$3>=$M10,F$3<=$N10),$B10/($N10-$M10+1),0) -> 0 | G10: =IF(AND(G$3>=$M10,G$3<=$N10),$B10/($N10-$M10+1),0) -> 13 | H10: =IF(AND(H$3>=$M10,H$3<=$N10),$B10/($N10-$M10+1),0) -> 13 | I10: =IF(AND(I$3>=$M10,I$3<=$N10),$B10/($N10-$M10+1),0) -> 0 | J10: =IF(AND(J$3>=$M10,J$3<=$N10),$B10/($N10-$M10+1),0) -> 0 | ... L10: =IF(AND(L$3>=$M10,L$3<=$N10),$B10/($N10-$M10+1),0) -> 0 | M10: =_xlfn.MINIFS(OTP!$J$4:$J$39,OTP!$C$4:$C$39,$A10) -> 10 | N10: =_xlfn.MAXIFS(OTP!$K$4:$K$39,OTP!$C$4:$C$39,$A10) -> 11 | O10: Non | P10: =OTP!A10&" "&LEFT(OTP!B10,42) -> T1.3 Provisionnement des VM/LXC avec Terraform | Q10: =OTP!J10 -> 7 | R10: =OTP!K10 -> 7 | S10: =Q10 -> 7 | T10: =IF(OTP!C10="Lot 0",R10-Q10+1,0) -> 0 | U10: =IF(AND(OTP!C10<>"Lot 0",INDEX($O$4:$O$12,MATCH(OTP!C10,$A$4:$A$12,0))<>"Oui"),R10-Q10+1,0) -> 0 | V10: =IF(AND(OTP!C10<>"Lot 0",INDEX($O$4:$O$12,MATCH(OTP!C10,$A$4:$A$12,0))="Oui"),R10-Q10+1,0) -> 1
A11: Lot 7 | B11: =SUMIF(OTP!$C:$C,A11,OTP!$F:$F) -> 32 | C11: =IF(AND(C$3>=$M11,C$3<=$N11),$B11/($N11-$M11+1),0) -> 0 | D11: =IF(AND(D$3>=$M11,D$3<=$N11),$B11/($N11-$M11+1),0) -> 0 | E11: =IF(AND(E$3>=$M11,E$3<=$N11),$B11/($N11-$M11+1),0) -> 0 | F11: =IF(AND(F$3>=$M11,F$3<=$N11),$B11/($N11-$M11+1),0) -> 0 | G11: =IF(AND(G$3>=$M11,G$3<=$N11),$B11/($N11-$M11+1),0) -> 0 | H11: =IF(AND(H$3>=$M11,H$3<=$N11),$B11/($N11-$M11+1),0) -> 0 | I11: =IF(AND(I$3>=$M11,I$3<=$N11),$B11/($N11-$M11+1),0) -> 16 | J11: =IF(AND(J$3>=$M11,J$3<=$N11),$B11/($N11-$M11+1),0) -> 16 | ... L11: =IF(AND(L$3>=$M11,L$3<=$N11),$B11/($N11-$M11+1),0) -> 0 | M11: =_xlfn.MINIFS(OTP!$J$4:$J$39,OTP!$C$4:$C$39,$A11) -> 12 | N11: =_xlfn.MAXIFS(OTP!$K$4:$K$39,OTP!$C$4:$C$39,$A11) -> 13 | O11: Oui | P11: =OTP!A11&" "&LEFT(OTP!B11,42) -> T1.4 Playbooks Ansible (automatisation centrali | Q11: =OTP!J11 -> 7 | R11: =OTP!K11 -> 8 | S11: =Q11 -> 7 | T11: =IF(OTP!C11="Lot 0",R11-Q11+1,0) -> 0 | U11: =IF(AND(OTP!C11<>"Lot 0",INDEX($O$4:$O$12,MATCH(OTP!C11,$A$4:$A$12,0))<>"Oui"),R11-Q11+1,0) -> 0 | V11: =IF(AND(OTP!C11<>"Lot 0",INDEX($O$4:$O$12,MATCH(OTP!C11,$A$4:$A$12,0))="Oui"),R11-Q11+1,0) -> 2
A12: Lot 8 | B12: =SUMIF(OTP!$C:$C,A12,OTP!$F:$F) -> 38 | C12: =IF(AND(C$3>=$M12,C$3<=$N12),$B12/($N12-$M12+1),0) -> 0 | D12: =IF(AND(D$3>=$M12,D$3<=$N12),$B12/($N12-$M12+1),0) -> 0 | E12: =IF(AND(E$3>=$M12,E$3<=$N12),$B12/($N12-$M12+1),0) -> 0 | F12: =IF(AND(F$3>=$M12,F$3<=$N12),$B12/($N12-$M12+1),0) -> 0 | G12: =IF(AND(G$3>=$M12,G$3<=$N12),$B12/($N12-$M12+1),0) -> 0 | H12: =IF(AND(H$3>=$M12,H$3<=$N12),$B12/($N12-$M12+1),0) -> 0 | I12: =IF(AND(I$3>=$M12,I$3<=$N12),$B12/($N12-$M12+1),0) -> 0 | J12: =IF(AND(J$3>=$M12,J$3<=$N12),$B12/($N12-$M12+1),0) -> 0 | ... L12: =IF(AND(L$3>=$M12,L$3<=$N12),$B12/($N12-$M12+1),0) -> 19 | M12: =_xlfn.MINIFS(OTP!$J$4:$J$39,OTP!$C$4:$C$39,$A12) -> 14 | N12: =_xlfn.MAXIFS(OTP!$K$4:$K$39,OTP!$C$4:$C$39,$A12) -> 15 | O12: Oui | P12: =OTP!A12&" "&LEFT(OTP!B12,42) -> T1.5 Orchestration de conteneurs avec Kubernete | Q12: =OTP!J12 -> 7 | R12: =OTP!K12 -> 13 | S12: =Q12 -> 7 | T12: =IF(OTP!C12="Lot 0",R12-Q12+1,0) -> 0 | U12: =IF(AND(OTP!C12<>"Lot 0",INDEX($O$4:$O$12,MATCH(OTP!C12,$A$4:$A$12,0))<>"Oui"),R12-Q12+1,0) -> 0 | V12: =IF(AND(OTP!C12<>"Lot 0",INDEX($O$4:$O$12,MATCH(OTP!C12,$A$4:$A$12,0))="Oui"),R12-Q12+1,0) -> 7
A13: Total / semaine | B13: =SUM(B4:B12) -> 346 | C13: =SUM(C4:C12) -> 15.375 | D13: =SUM(D4:D12) -> 15.375 | E13: =SUM(E4:E12) -> 29.375 | F13: =SUM(F4:F12) -> 29.375 | G13: =SUM(G4:G12) -> 58.875 | H13: =SUM(H4:H12) -> 58.875 | I13: =SUM(I4:I12) -> 55.375 | ... L13: =SUM(L4:L12) -> 26 | P13: =OTP!A13&" "&LEFT(OTP!B13,42) -> T1.6 Plan d'adressage IP et segmentation VLAN | Q13: =OTP!J13 -> 7 | R13: =OTP!K13 -> 7 | S13: =Q13 -> 7 | T13: =IF(OTP!C13="Lot 0",R13-Q13+1,0) -> 0 | U13: =IF(AND(OTP!C13<>"Lot 0",INDEX($O$4:$O$12,MATCH(OTP!C13,$A$4:$A$12,0))<>"Oui"),R13-Q13+1,0) -> 0 | V13: =IF(AND(OTP!C13<>"Lot 0",INDEX($O$4:$O$12,MATCH(OTP!C13,$A$4:$A$12,0))="Oui"),R13-Q13+1,0) -> 1
A14: Charge cumulée (h) | C14: =C13 -> 15.375 | D14: =C14+D13 -> 30.75 | E14: =D14+E13 -> 60.125 | F14: =E14+F13 -> 89.5 | G14: =F14+G13 -> 148.375 | H14: =G14+H13 -> 207.25 | I14: =H14+I13 -> 262.625 | J14: =I14+J13 -> 294 | K14: =J14+K13 -> 320 | L14: =K14+L13 -> 346 | P14: =OTP!A14&" "&LEFT(OTP!B14,42) -> T2.1 Installation du pare-feu pfSense/OPNsense | Q14: =OTP!J14 -> 8 | R14: =OTP!K14 -> 8 | S14: =Q14 -> 8 | T14: =IF(OTP!C14="Lot 0",R14-Q14+1,0) -> 0 | U14: =IF(AND(OTP!C14<>"Lot 0",INDEX($O$4:$O$12,MATCH(OTP!C14,$A$4:$A$12,0))<>"Oui"),R14-Q14+1,0) -> 0 | V14: =IF(AND(OTP!C14<>"Lot 0",INDEX($O$4:$O$12,MATCH(OTP!C14,$A$4:$A$12,0))="Oui"),R14-Q14+1,0) -> 1
P15: =OTP!A15&" "&LEFT(OTP!B15,42) -> T2.2 Configuration du VPN avec Tailscale | Q15: =OTP!J15 -> 8 | R15: =OTP!K15 -> 9 | S15: =Q15 -> 8 | T15: =IF(OTP!C15="Lot 0",R15-Q15+1,0) -> 0 | U15: =IF(AND(OTP!C15<>"Lot 0",INDEX($O$4:$O$12,MATCH(OTP!C15,$A$4:$A$12,0))<>"Oui"),R15-Q15+1,0) -> 0 | V15: =IF(AND(OTP!C15<>"Lot 0",INDEX($O$4:$O$12,MATCH(OTP!C15,$A$4:$A$12,0))="Oui"),R15-Q15+1,0) -> 2
P16: =OTP!A16&" "&LEFT(OTP!B16,42) -> T2.3 Règles de pare-feu et segmentation | Q16: =OTP!J16 -> 9 | R16: =OTP!K16 -> 9 | S16: =Q16 -> 9 | T16: =IF(OTP!C16="Lot 0",R16-Q16+1,0) -> 0 | U16: =IF(AND(OTP!C16<>"Lot 0",INDEX($O$4:$O$12,MATCH(OTP!C16,$A$4:$A$12,0))<>"Oui"),R16-Q16+1,0) -> 0 | V16: =IF(AND(OTP!C16<>"Lot 0",INDEX($O$4:$O$12,MATCH(OTP!C16,$A$4:$A$12,0))="Oui"),R16-Q16+1,0) -> 1
P17: =OTP!A17&" "&LEFT(OTP!B17,42) -> T2.4 Reverse proxy et HTTPS avec Caddy | Q17: =OTP!J17 -> 9 | R17: =OTP!K17 -> 9 | S17: =Q17 -> 9 | T17: =IF(OTP!C17="Lot 0",R17-Q17+1,0) -> 0 | U17: =IF(AND(OTP!C17<>"Lot 0",INDEX($O$4:$O$12,MATCH(OTP!C17,$A$4:$A$12,0))<>"Oui"),R17-Q17+1,0) -> 0 | V17: =IF(AND(OTP!C17<>"Lot 0",INDEX($O$4:$O$12,MATCH(OTP!C17,$A$4:$A$12,0))="Oui"),R17-Q17+1,0) -> 1
P18: =OTP!A18&" "&LEFT(OTP!B18,42) -> T3.1 Service VoIP avec Asterisk | Q18: =OTP!J18 -> 10 | R18: =OTP!K18 -> 11 | S18: =Q18 -> 10 | T18: =IF(OTP!C18="Lot 0",R18-Q18+1,0) -> 0 | U18: =IF(AND(OTP!C18<>"Lot 0",INDEX($O$4:$O$12,MATCH(OTP!C18,$A$4:$A$12,0))<>"Oui"),R18-Q18+1,0) -> 0 | V18: =IF(AND(OTP!C18<>"Lot 0",INDEX($O$4:$O$12,MATCH(OTP!C18,$A$4:$A$12,0))="Oui"),R18-Q18+1,0) -> 2
P19: =OTP!A19&" "&LEFT(OTP!B19,42) -> T3.2 Serveur de développement web (Apache, Mari | Q19: =OTP!J19 -> 10 | R19: =OTP!K19 -> 11 | S19: =Q19 -> 10 | T19: =IF(OTP!C19="Lot 0",R19-Q19+1,0) -> 0 | U19: =IF(AND(OTP!C19<>"Lot 0",INDEX($O$4:$O$12,MATCH(OTP!C19,$A$4:$A$12,0))<>"Oui"),R19-Q19+1,0) -> 0 | V19: =IF(AND(OTP!C19<>"Lot 0",INDEX($O$4:$O$12,MATCH(OTP!C19,$A$4:$A$12,0))="Oui"),R19-Q19+1,0) -> 2
P20: =OTP!A20&" "&LEFT(OTP!B20,42) -> T3.3 Supervision des ressources avec Netdata | Q20: =OTP!J20 -> 11 | R20: =OTP!K20 -> 11 | S20: =Q20 -> 11 | T20: =IF(OTP!C20="Lot 0",R20-Q20+1,0) -> 0 | U20: =IF(AND(OTP!C20<>"Lot 0",INDEX($O$4:$O$12,MATCH(OTP!C20,$A$4:$A$12,0))<>"Oui"),R20-Q20+1,0) -> 0 | V20: =IF(AND(OTP!C20<>"Lot 0",INDEX($O$4:$O$12,MATCH(OTP!C20,$A$4:$A$12,0))="Oui"),R20-Q20+1,0) -> 1
P21: =OTP!A21&" "&LEFT(OTP!B21,42) -> T4.1 Déploiement d'Active Directory Domain Serv | Q21: =OTP!J21 -> 10 | R21: =OTP!K21 -> 10 | S21: =Q21 -> 10 | T21: =IF(OTP!C21="Lot 0",R21-Q21+1,0) -> 0 | U21: =IF(AND(OTP!C21<>"Lot 0",INDEX($O$4:$O$12,MATCH(OTP!C21,$A$4:$A$12,0))<>"Oui"),R21-Q21+1,0) -> 0 | V21: =IF(AND(OTP!C21<>"Lot 0",INDEX($O$4:$O$12,MATCH(OTP!C21,$A$4:$A$12,0))="Oui"),R21-Q21+1,0) -> 1
P22: =OTP!A22&" "&LEFT(OTP!B22,42) -> T4.2 Serveur de courriel avec hMailServer | Q22: =OTP!J22 -> 10 | R22: =OTP!K22 -> 11 | S22: =Q22 -> 10 | T22: =IF(OTP!C22="Lot 0",R22-Q22+1,0) -> 0 | U22: =IF(AND(OTP!C22<>"Lot 0",INDEX($O$4:$O$12,MATCH(OTP!C22,$A$4:$A$12,0))<>"Oui"),R22-Q22+1,0) -> 0 | V22: =IF(AND(OTP!C22<>"Lot 0",INDEX($O$4:$O$12,MATCH(OTP!C22,$A$4:$A$12,0))="Oui"),R22-Q22+1,0) -> 2
P23: =OTP!A23&" "&LEFT(OTP!B23,42) -> T4.3 Gestion des tickets avec osTicket | Q23: =OTP!J23 -> 10 | R23: =OTP!K23 -> 11 | S23: =Q23 -> 10 | T23: =IF(OTP!C23="Lot 0",R23-Q23+1,0) -> 0 | U23: =IF(AND(OTP!C23<>"Lot 0",INDEX($O$4:$O$12,MATCH(OTP!C23,$A$4:$A$12,0))<>"Oui"),R23-Q23+1,0) -> 0 | V23: =IF(AND(OTP!C23<>"Lot 0",INDEX($O$4:$O$12,MATCH(OTP!C23,$A$4:$A$12,0))="Oui"),R23-Q23+1,0) -> 2
P24: =OTP!A24&" "&LEFT(OTP!B24,42) -> T4.4 Sauvegardes avec Veeam Backup & Replicatio | Q24: =OTP!J24 -> 11 | R24: =OTP!K24 -> 11 | S24: =Q24 -> 11 | T24: =IF(OTP!C24="Lot 0",R24-Q24+1,0) -> 0 | U24: =IF(AND(OTP!C24<>"Lot 0",INDEX($O$4:$O$12,MATCH(OTP!C24,$A$4:$A$12,0))<>"Oui"),R24-Q24+1,0) -> 0 | V24: =IF(AND(OTP!C24<>"Lot 0",INDEX($O$4:$O$12,MATCH(OTP!C24,$A$4:$A$12,0))="Oui"),R24-Q24+1,0) -> 1
P25: =OTP!A25&" "&LEFT(OTP!B25,42) -> T4.5 Déploiement de Microsoft Defender for Endp | Q25: =OTP!J25 -> 10 | R25: =OTP!K25 -> 11 | S25: =Q25 -> 10 | T25: =IF(OTP!C25="Lot 0",R25-Q25+1,0) -> 0 | U25: =IF(AND(OTP!C25<>"Lot 0",INDEX($O$4:$O$12,MATCH(OTP!C25,$A$4:$A$12,0))<>"Oui"),R25-Q25+1,0) -> 0 | V25: =IF(AND(OTP!C25<>"Lot 0",INDEX($O$4:$O$12,MATCH(OTP!C25,$A$4:$A$12,0))="Oui"),R25-Q25+1,0) -> 2
P26: =OTP!A26&" "&LEFT(OTP!B26,42) -> T5.1 Script d'automatisation individuel | Q26: =OTP!J26 -> 12 | R26: =OTP!K26 -> 12 | S26: =Q26 -> 12 | T26: =IF(OTP!C26="Lot 0",R26-Q26+1,0) -> 0 | U26: =IF(AND(OTP!C26<>"Lot 0",INDEX($O$4:$O$12,MATCH(OTP!C26,$A$4:$A$12,0))<>"Oui"),R26-Q26+1,0) -> 1 | V26: =IF(AND(OTP!C26<>"Lot 0",INDEX($O$4:$O$12,MATCH(OTP!C26,$A$4:$A$12,0))="Oui"),R26-Q26+1,0) -> 0
... P39: =OTP!A39&" "&LEFT(OTP!B39,42) -> T8.4 Préparation de la présentation finale | Q39: =OTP!J39 -> 15 | R39: =OTP!K39 -> 15 | S39: =Q39 -> 15 | T39: =IF(OTP!C39="Lot 0",R39-Q39+1,0) -> 0 | U39: =IF(AND(OTP!C39<>"Lot 0",INDEX($O$4:$O$12,MATCH(OTP!C39,$A$4:$A$12,0))<>"Oui"),R39-Q39+1,0) -> 0 | V39: =IF(AND(OTP!C39<>"Lot 0",INDEX($O$4:$O$12,MATCH(OTP!C39,$A$4:$A$12,0))="Oui"),R39-Q39+1,0) -> 1
